Workbook

Sheet Cover
A1: Alphabet Inc. (GOOG/GOOGL)
A2: Segment-Driven DCF Model | v5 | 2026-02-10
A4: 数据来源 Data Sources | B4: Alphabet 2025 10-K + Q4'25 Earnings Call + FRED
A5: CapEx 2026 指引 | B5: $75B/quarter → annualized ~$180B (earnings call 2026-02-04)
A6: 模型特色 Key Feature | B6: 11-Tab model: 三表联动 (PL + BS + CF) + Segment P&L 交叉验证
B7: Dual-layer P&L: Segment_PL (by division) + Consolidated_PL (by cost type)
A9: 使用步骤 HOW TO USE
A10: Step 1 | B10: Go to Assumptions → edit BLUE cells only (蓝底单元格)
A11: Step 2 | B11: Switch scenario: Assumptions!B2 → Base / Bull / Bear
A12: Step 3 | B12: All tabs auto-update: Revenue → Segment PL → Consolidated PL → BS → CF → DCF
A13: Step 4 | B13: Check Segment_PL cross-check row: difference should = 0
A14: Step 5 | B14: Check BS balance check row: Total Assets = Total L&E
A15: Step 6 | B15: Every assumption shows HISTORICAL values (2023-2025) for reference
A16: Step 7 | B16: Notes column (col J) explains prediction logic for every row

Sheet Key_Summary
A1: Alphabet Inc. (GOOG) - 财务摘要 Executive Summary
A2: 单位：百万美元（USD Million）
A4: 核心财务指标 Key Financial Highlights | B4: 2023A | C4: 2024A | D4: 2025A | E4: 2026E | F4: 2027E | G4: 2028E | H4: 说明 Notes
A5: 总收入 Total Revenue | B5: =Consolidated_PL!B5 | C5: =Consolidated_PL!C5 | D5: =Consolidated_PL!D5 | E5: =Consolidated_PL!E5 | F5: =Consolidated_PL!F5 | G5: =Consolidated_PL!G5 | H5: 链接自Consolidated_PL
A6: YoY增速 % | C6: =C5/B5-1 | D6: =D5/C5-1 | E6: =E5/D5-1 | F6: =F5/E5-1 | G6: =G5/F5-1
A7: 毛利润 Gross Profit | B7: =Consolidated_PL!B15 | C7: =Consolidated_PL!C15 | D7: =Consolidated_PL!D15 | E7: =Consolidated_PL!E15 | F7: =Consolidated_PL!F15 | G7: =Consolidated_PL!G15
A8: 毛利率 GPM % | B8: =B7/B5 | C8: =C7/C5 | D8: =D7/D5 | E8: =E7/E5 | F8: =F7/F5 | G8: =G7/G5
A9: 营业利润 EBIT | B9: =Consolidated_PL!B26 | C9: =Consolidated_PL!C26 | D9: =Consolidated_PL!D26 | E9: =Consolidated_PL!E26 | F9: =Consolidated_PL!F26 | G9: =Consolidated_PL!G26
A10: 营业利润率 OPM % | B10: =B9/B5 | C10: =C9/C5 | D10: =D9/D5 | E10: =E9/E5 | F10: =F9/F5 | G10: =G9/G5
A11: 净利润 Net Income | B11: =Consolidated_PL!B33 | C11: =Consolidated_PL!C33 | D11: =Consolidated_PL!D33 | E11: =Consolidated_PL!E33 | F11: =Consolidated_PL!F33 | G11: =Consolidated_PL!G33
A12: 净利率 NPM % | B12: =B11/B5 | C12: =C11/C5 | D12: =D11/D5 | E12: =E11/E5 | F12: =F11/F5 | G12: =G11/G5
A13: NI YoY % | C13: =C12/B12-1 | D13: =D12/C12-1 | E13: =E12/D12-1 | F13: =F12/E12-1 | G13: =G12/F12-1
A14: 稀释EPS | B14: =Consolidated_PL!B41 | C14: =Consolidated_PL!C41 | D14: =Consolidated_PL!D41 | E14: =Consolidated_PL!E41 | F14: =Consolidated_PL!F41 | G14: =Consolidated_PL!G41
A16: 分部收入结构 Revenue by Segment | B16: 2023A | C16: 2024A | D16: 2025A | E16: 2026E | F16: 2027E | G16: 2028E | H16: 说明 Notes
A17: Google Services Total | B17: =Segment_Revenue!B19 | C17: =Segment_Revenue!C19 | D17: =Segment_Revenue!D19 | E17: =Segment_Revenue!E19 | F17: =Segment_Revenue!F19 | G17: =Segment_Revenue!G19
A18: 占比 % | B18: =B17/B5 | C18: =C17/C5 | D18: =D17/D5 | E18: =E17/E5 | F18: =F17/F5 | G18: =G17/G5
A19: Google Cloud | B19: =Segment_Revenue!B22 | C19: =Segment_Revenue!C22 | D19: =Segment_Revenue!D22 | E19: =Segment_Revenue!E22 | F19: =Segment_Revenue!F22 | G19: =Segment_Revenue!G22
A20: 占比 % | B20: =B19/B5 | C20: =C19/C5 | D20: =D19/D5 | E20: =E19/E5 | F20: =F19/F5 | G20: =G19/G5
A21: Other Bets | B21: =Segment_Revenue!B26 | C21: =Segment_Revenue!C26 | D21: =Segment_Revenue!D26 | E21: =Segment_Revenue!E26 | F21: =Segment_Revenue!F26 | G21: =Segment_Revenue!G26
A22: 占比 % | B22: =B21/B5 | C22: =C21/C5 | D22: =D21/D5 | E22: =E21/E5 | F22: =F21/F5 | G22: =G21/G5
A24: 资产负债核心指标 Balance Sheet Highlights | B24: 2023A | C24: 2024A | D24: 2025A | E24: 2026E | F24: 2027E | G24: 2028E | H24: 说明
A25: 总资产 Total Assets | B25: =BS!B21 | C25: =BS!C21 | D25: =BS!D21 | E25: =BS!E21 | F25: =BS!F21 | G25: =BS!G21
A26: 股东权益 Total Equity | B26: =BS!B40 | C26: =BS!C40 | D26: =BS!D40 | E26: =BS!E40 | F26: =BS!F40 | G26: =BS!G40
A27: 现金及证券 Cash & Securities | B27: =BS!B8 | C27: =BS!C8 | D27: =BS!D8 | E27: =BS!E8 | F27: =BS!F8 | G27: =BS!G8
A28: ROE 净资产收益率 | B28: =B11/B26 | C28: =C11/C26 | D28: =D11/D26 | E28: =E11/E26 | F28: =F11/F26 | G28: =G11/G26 | H28: 净利润/权益
A29: ROA 总资产收益率 | B29: =B11/B25 | C29: =C11/C25 | D29: =D11/D25 | E29: =E11/E25 | F29: =F11/F25 | G29: =G11/G25 | H29: 净利润/总资产
A32: 关键投资亮点 Key Investment Highlights
A33: ✓ AI驱动搜索广告核心引擎，Search+YouTube贡献>65%收入
A34: ✓ Google Cloud 48% YoY增长(Q4'25)，利润率从5%→24%快速提升
A35: ✓ AI CapEx高峰投资($180B/2026)确立长期竞争壁垒
A36: ✓ 稳健股东回报：年回购~$50B + 股息$0.88/share
A37: ✓ Net cash >$80B，资产负债表极其稳健
A38: ⚠ 风险：AI CapEx回报不确定、DOJ反垄断、Cloud竞争激烈
A40: 数据图例 Data Legend:
A41: 蓝色字体 Blue Font = 财报原始数据 Hardcoded from financials
A42: 绿色字体 Green Font = 链接自其他工作表 Links from other sheets
A43: 蓝底深蓝字体 Blue Fill = 可编辑假设 Editable assumption inputs
A44: 黄底粗体 Yellow Fill = 关键输出 Key output rows
... A51: • 10Y UST yield ~4.2% (Feb 2026), Fed 2% long-term inflation target

Sheet Assumptions
A1: Assumptions & Drivers 假设与驱动
A2: Scenario 情景 | B2: Base
A4: Parameter 参数 | B4: 2023A | C4: 2024A | D4: 2025A | F4: Base | G4: Bull | H4: Bear | I4: Selected | K4: Notes / 预测逻辑
A6: WACC 加权平均资本成本参数
A7: Risk-Free Rate 无风险利率 (10Y UST) | F7: 0.042 | G7: 0.042 | H7: 0.042 | I7: =CHOOSE(MATCH($B$2,{"Base","Bull","Bear"},0),F7,G7,H7) | K7: 10Y美债收益率 ~4.2% (Feb 2026)
A8: Equity Beta 权益Beta | F8: 1.05 | G8: 1 | H8: 1.1 | I8: =CHOOSE(MATCH($B$2,{"Base","Bull","Bear"},0),F8,G8,H8) | K8: 参考Bloomberg/Reuters 5Y weekly beta
A9: Equity Risk Premium ERP 股权风险溢价 | F9: 0.05 | G9: 0.052 | H9: 0.048 | I9: =CHOOSE(MATCH($B$2,{"Base","Bull","Bear"},0),F9,G9,H9) | K9: Damodaran 2026 ERP estimate
A10: Pre-tax Cost of Debt Kd 税前债务成本 | F10: 0.049 | G10: 0.048 | H10: 0.052 | I10: =CHOOSE(MATCH($B$2,{"Base","Bull","Bear"},0),F10,G10,H10) | K10: 参考Alphabet最新债券到期收益率
A11: Effective Tax Rate 有效税率 | B11: 0.139 | C11: 0.164 | D11: 0.168 | F11: 0.17 | G11: 0.165 | H11: 0.18 | I11: =CHOOSE(MATCH($B$2,{"Base","Bull","Bear"},0),F11,G11,H11) | K11: 2023-2025历史税率参考
A12: Debt / Total Capital 债务占比 | F12: 0.03 | G12: 0.025 | H12: 0.035 | I12: =CHOOSE(MATCH($B$2,{"Base","Bull","Bear"},0),F12,G12,H12) | K12: Alphabet资本结构以权益为主
A13: Terminal Growth Rate g 永续增长率 | F13: 0.03 | G13: 0.033 | H13: 0.027 | I13: =CHOOSE(MATCH($B$2,{"Base","Bull","Bear"},0),F13,G13,H13) | K13: 约=长期GDP增长+通胀
A15: Derived WACC 推导的WACC
A16: Ke = Rf + Beta × ERP 股权成本 | I16: =I7+I8*I9
A17: After-tax Kd 税后债务成本 | I17: =I10*(1-I11)
A18: WACC 加权平均资本成本 | I18: =(1-I12)*I16+I12*I17
A20: Valuation Bridge 估值桥接
A21: Cash & Marketable Securities 现金及有价证券 (mm) | B21: 110916 | C21: 95657 | D21: 126843 | F21: 126843 | G21: 126843 | H21: 126843 | I21: =CHOOSE(MATCH($B$2,{"Base","Bull","Bear"},0),F21,G21,H21) | K21: 年末现金+短期证券合计
A22: Total Debt 总债务 (mm) | B22: 12887 | C22: 10883 | D22: 46547 | F22: 46547 | G22: 46547 | H22: 46547 | I22: =CHOOSE(MATCH($B$2,{"Base","Bull","Bear"},0),F22,G22,H22) | K22: 短期+长期债务
A23: Diluted Shares 稀释股数 (mm) | B23: 12722 | C23: 12447 | D23: 12230 | F23: 12230 | G23: 12230 | H23: 12230 | I23: =CHOOSE(MATCH($B$2,{"Base","Bull","Bear"},0),F23,G23,H23) | K23: Source: 10-K p.49
A25: Revenue Growth by Segment 分部收入增长率 (Base块)
A26: Segment | B26: 2023A | C26: 2024A | D26: 2025A | F26: 2026E | G26: 2027E | H26: 2028E | I26: 2029E | J26: 2030E
A27: Google Search & other | C27: 0.13169517 | D27: 0.13351911 | F27: 0.12 | G27: 0.1 | H27: 0.09 | I27: 0.08 | J27: 0.07 | K27: 搜索广告核心引擎
A28: YouTube ads | C28: 0.14715963 | D28: 0.11674551 | F28: 0.14 | G28: 0.12 | H28: 0.1 | I28: 0.09 | J28: 0.08 | K28: AI-driven Shorts增长
A29: Google Network | C29: -0.030435616 | D29: -0.018676504 | F29: -0.02 | G29: -0.02 | H29: -0.01 | I29: -0.01 | J29: 0 | K29: 持续缩减
A30: Subs, Platforms & Devices | C30: 0.16293819 | D30: 0.19062965 | F30: 0.18 | G30: 0.15 | H30: 0.13 | I30: 0.11 | J30: 0.09 | K30: YouTube Premium/硬件增长
A31: Google Cloud | C31: 0.30648574 | D31: 0.35800042 | F31: 0.3 | G31: 0.25 | H31: 0.22 | I31: 0.18 | J31: 0.15 | K31: AI Cloud高增长引擎
A32: Other Bets | C32: 0.079240341 | D32: -0.067354369 | F32: 0.1 | G32: 0.15 | H32: 0.15 | I32: 0.15 | J32: 0.1 | K32: Waymo等前沿业务
A34: Revenue Growth - Bull Case 乐观情景
A35: Google Search & other | F35: 0.15 | G35: 0.13 | H35: 0.11 | I35: 0.1 | J35: 0.09
A36: YouTube ads | F36: 0.18 | G36: 0.15 | H36: 0.13 | I36: 0.11 | J36: 0.1
A37: Google Network | F37: -0.01 | G37: 0 | H37: 0 | I37: 0.01 | J37: 0.01
A38: Subs, Platforms & Devices | F38: 0.22 | G38: 0.18 | H38: 0.15 | I38: 0.13 | J38: 0.11
A39: Google Cloud | F39: 0.38 | G39: 0.3 | H39: 0.25 | I39: 0.2 | J39: 0.17
A40: Other Bets | F40: 0.15 | G40: 0.2 | H40: 0.2 | I40: 0.2 | J40: 0.15
A42: Revenue Growth - Bear Case 悲观情景
A43: Google Search & other | F43: 0.08 | G43: 0.07 | H43: 0.06 | I43: 0.05 | J43: 0.04
A44: YouTube ads | F44: 0.08 | G44: 0.07 | H44: 0.06 | I44: 0.05 | J44: 0.04
A45: Google Network | F45: -0.05 | G45: -0.04 | H45: -0.03 | I45: -0.03 | J45: -0.02
A46: Subs, Platforms & Devices | F46: 0.12 | G46: 0.1 | H46: 0.09 | I46: 0.08 | J46: 0.07
A47: Google Cloud | F47: 0.22 | G47: 0.18 | H47: 0.15 | I47: 0.12 | J47: 0.1
...

Sheet Segment_Revenue
A1: Revenue Build 分部收入构建 (USD mm)
A2: 单位：百万美元 | Cloud Q4'25 = $17.7B (48% YoY)
B4: 2023 | C4: 2024 | D4: 2025 | E4: 2026E | F4: 2027E | G4: 2028E | H4: 2029E | I4: 2030E | K4: Notes / 预测逻辑
A6: Google Advertising 谷歌广告
A7: Google Search & other | B7: 175033 | C7: 198084 | D7: 224532 | E7: =D7*(1+CHOOSE(MATCH(Assumptions!$B$2,{"Base","Bull","Bear"},0),Assumptions!F$27,Assumptions!F$35,Assumptions!F$43)) | F7: =E7*(1+CHOOSE(MATCH(Assumptions!$B$2,{"Base","Bull","Bear"},0),Assumptions!G$27,Assumptions!G$35,Assumptions!G$43)) | G7: =F7*(1+CHOOSE(MATCH(Assumptions!$B$2,{"Base","Bull","Bear"},0),Assumptions!H$27,Assumptions!H$35,Assumptions!H$43)) | H7: =G7*(1+CHOOSE(MATCH(Assumptions!$B$2,{"Base","Bull","Bear"},0),Assumptions!I$27,Assumptions!I$35,Assumptions!I$43)) | I7: =H7*(1+CHOOSE(MATCH(Assumptions!$B$2,{"Base","Bull","Bear"},0),Assumptions!J$27,Assumptions!J$35,Assumptions!J$43)) | K7: 搜索广告核心收入，AI Overview推动
A8: yoy % | C8: =C7/B7-1 | D8: =D7/C7-1 | E8: =E7/D7-1 | F8: =F7/E7-1 | G8: =G7/F7-1 | H8: =H7/G7-1 | I8: =I7/H7-1
A9: YouTube ads | B9: 31510 | C9: 36147 | D9: 40367 | E9: =D9*(1+CHOOSE(MATCH(Assumptions!$B$2,{"Base","Bull","Bear"},0),Assumptions!F$28,Assumptions!F$36,Assumptions!F$44)) | F9: =E9*(1+CHOOSE(MATCH(Assumptions!$B$2,{"Base","Bull","Bear"},0),Assumptions!G$28,Assumptions!G$36,Assumptions!G$44)) | G9: =F9*(1+CHOOSE(MATCH(Assumptions!$B$2,{"Base","Bull","Bear"},0),Assumptions!H$28,Assumptions!H$36,Assumptions!H$44)) | H9: =G9*(1+CHOOSE(MATCH(Assumptions!$B$2,{"Base","Bull","Bear"},0),Assumptions!I$28,Assumptions!I$36,Assumptions!I$44)) | I9: =H9*(1+CHOOSE(MATCH(Assumptions!$B$2,{"Base","Bull","Bear"},0),Assumptions!J$28,Assumptions!J$36,Assumptions!J$44)) | K9: Shorts变现+Connected TV增长
A10: yoy % | C10: =C9/B9-1 | D10: =D9/C9-1 | E10: =E9/D9-1 | F10: =F9/E9-1 | G10: =G9/F9-1 | H10: =H9/G9-1 | I10: =I9/H9-1
A11: Google Network | B11: 31312 | C11: 30359 | D11: 29792 | E11: =D11*(1+CHOOSE(MATCH(Assumptions!$B$2,{"Base","Bull","Bear"},0),Assumptions!F$29,Assumptions!F$37,Assumptions!F$45)) | F11: =E11*(1+CHOOSE(MATCH(Assumptions!$B$2,{"Base","Bull","Bear"},0),Assumptions!G$29,Assumptions!G$37,Assumptions!G$45)) | G11: =F11*(1+CHOOSE(MATCH(Assumptions!$B$2,{"Base","Bull","Bear"},0),Assumptions!H$29,Assumptions!H$37,Assumptions!H$45)) | H11: =G11*(1+CHOOSE(MATCH(Assumptions!$B$2,{"Base","Bull","Bear"},0),Assumptions!I$29,Assumptions!I$37,Assumptions!I$45)) | I11: =H11*(1+CHOOSE(MATCH(Assumptions!$B$2,{"Base","Bull","Bear"},0),Assumptions!J$29,Assumptions!J$37,Assumptions!J$45)) | K11: 持续萎缩，向自有平台转移
A12: yoy % | C12: =C11/B11-1 | D12: =D11/C11-1 | E12: =E11/D11-1 | F12: =F11/E11-1 | G12: =G11/F11-1 | H12: =H11/G11-1 | I12: =I11/H11-1
A13: Total Google Advertising 广告合计 | B13: =B7+B9+B11 | C13: =C7+C9+C11 | D13: =D7+D9+D11 | E13: =E7+E9+E11 | F13: =F7+F9+F11 | G13: =G7+G9+G11 | H13: =H7+H9+H11 | I13: =I7+I9+I11 | K13: Search+YouTube+Network
A15: Subscriptions, Platforms & Devices 订阅/平台/设备
A16: Subs, Platforms & Devices | B16: 34688 | C16: 40340 | D16: 48030 | E16: =D16*(1+CHOOSE(MATCH(Assumptions!$B$2,{"Base","Bull","Bear"},0),Assumptions!F$30,Assumptions!F$38,Assumptions!F$46)) | F16: =E16*(1+CHOOSE(MATCH(Assumptions!$B$2,{"Base","Bull","Bear"},0),Assumptions!G$30,Assumptions!G$38,Assumptions!G$46)) | G16: =F16*(1+CHOOSE(MATCH(Assumptions!$B$2,{"Base","Bull","Bear"},0),Assumptions!H$30,Assumptions!H$38,Assumptions!H$46)) | H16: =G16*(1+CHOOSE(MATCH(Assumptions!$B$2,{"Base","Bull","Bear"},0),Assumptions!I$30,Assumptions!I$38,Assumptions!I$46)) | I16: =H16*(1+CHOOSE(MATCH(Assumptions!$B$2,{"Base","Bull","Bear"},0),Assumptions!J$30,Assumptions!J$38,Assumptions!J$46)) | K16: YouTube Premium/Music + Pixel设备
A17: yoy % | C17: =C16/B16-1 | D17: =D16/C16-1 | E17: =E16/D16-1 | F17: =F16/E16-1 | G17: =G16/F16-1 | H17: =H16/G16-1 | I17: =I16/H16-1
A19: Google Services Total 谷歌服务合计 | B19: =B13+B16 | C19: =C13+C16 | D19: =D13+D16 | E19: =E13+E16 | F19: =F13+F16 | G19: =G13+G16 | H19: =H13+H16 | I19: =I13+I16 | K19: 广告合计+订阅/平台/设备
A21: Google Cloud 谷歌云
A22: Google Cloud | B22: 33088 | C22: 43229 | D22: 58705 | E22: =D22*(1+CHOOSE(MATCH(Assumptions!$B$2,{"Base","Bull","Bear"},0),Assumptions!F$31,Assumptions!F$39,Assumptions!F$47)) | F22: =E22*(1+CHOOSE(MATCH(Assumptions!$B$2,{"Base","Bull","Bear"},0),Assumptions!G$31,Assumptions!G$39,Assumptions!G$47)) | G22: =F22*(1+CHOOSE(MATCH(Assumptions!$B$2,{"Base","Bull","Bear"},0),Assumptions!H$31,Assumptions!H$39,Assumptions!H$47)) | H22: =G22*(1+CHOOSE(MATCH(Assumptions!$B$2,{"Base","Bull","Bear"},0),Assumptions!I$31,Assumptions!I$39,Assumptions!I$47)) | I22: =H22*(1+CHOOSE(MATCH(Assumptions!$B$2,{"Base","Bull","Bear"},0),Assumptions!J$31,Assumptions!J$39,Assumptions!J$47)) | K22: GCP+Workspace，AI Cloud核心增长引擎
A23: yoy % | C23: =C22/B22-1 | D23: =D22/C22-1 | E23: =E22/D22-1 | F23: =F22/E22-1 | G23: =G22/F22-1 | H23: =H22/G22-1 | I23: =I22/H22-1
A25: Other Bets 其他创新业务
A26: Other Bets | B26: 1527 | C26: 1648 | D26: 1537 | E26: =D26*(1+CHOOSE(MATCH(Assumptions!$B$2,{"Base","Bull","Bear"},0),Assumptions!F$32,Assumptions!F$40,Assumptions!F$48)) | F26: =E26*(1+CHOOSE(MATCH(Assumptions!$B$2,{"Base","Bull","Bear"},0),Assumptions!G$32,Assumptions!G$40,Assumptions!G$48)) | G26: =F26*(1+CHOOSE(MATCH(Assumptions!$B$2,{"Base","Bull","Bear"},0),Assumptions!H$32,Assumptions!H$40,Assumptions!H$48)) | H26: =G26*(1+CHOOSE(MATCH(Assumptions!$B$2,{"Base","Bull","Bear"},0),Assumptions!I$32,Assumptions!I$40,Assumptions!I$48)) | I26: =H26*(1+CHOOSE(MATCH(Assumptions!$B$2,{"Base","Bull","Bear"},0),Assumptions!J$32,Assumptions!J$40,Assumptions!J$48)) | K26: Waymo/Verily等前沿业务
A27: yoy % | C27: =C26/B26-1 | D27: =D26/C26-1 | E27: =E26/D26-1 | F27: =F26/E26-1 | G27: =G26/F26-1 | H27: =H26/G26-1 | I27: =I26/H26-1
A29: Hedging gains (losses) 外汇对冲 | B29: 236 | C29: 211 | D29: -127 | E29: 0 | F29: 0 | G29: 0 | H29: 0 | I29: 0 | K29: 假设为零 Assume zero
A31: Total Revenue 总收入 | B31: =B19+B22+B26+B29 | C31: =C19+C22+C26+C29 | D31: =D19+D22+D26+D29 | E31: =E19+E22+E26+E29 | F31: =F19+F22+F26+F29 | G31: =G19+G22+G26+G29 | H31: =H19+H22+H26+H29 | I31: =I19+I22+I26+I29 | K31: Services+Cloud+OtherBets+Hedging
A32: yoy % | C32: =C31/B31-1 | D32: =D31/C31-1 | E32: =E31/D31-1 | F32: =F31/E31-1 | G32: =G31/F31-1 | H32: =H31/G31-1 | I32: =I31/H31-1
A34: Revenue Mix % 收入结构
A35: Google Search & other | B35: =B7/B31 | C35: =C7/C31 | D35: =D7/D31 | E35: =E7/E31 | F35: =F7/F31 | G35: =G7/G31 | H35: =H7/H31 | I35: =I7/I31
A36: YouTube ads | B36: =B9/B31 | C36: =C9/C31 | D36: =D9/D31 | E36: =E9/E31 | F36: =F9/F31 | G36: =G9/G31 | H36: =H9/H31 | I36: =I9/I31
A37: Google Network | B37: =B11/B31 | C37: =C11/C31 | D37: =D11/D31 | E37: =E11/E31 | F37: =F11/F31 | G37: =G11/G31 | H37: =H11/H31 | I37: =I11/I31
A38: Subs, Platforms & Devices | B38: =B16/B31 | C38: =C16/C31 | D38: =D16/D31 | E38: =E16/E31 | F38: =F16/F31 | G38: =G16/G31 | H38: =H16/H31 | I38: =I16/I31
A39: Google Cloud | B39: =B22/B31 | C39: =C22/C31 | D39: =D22/D31 | E39: =E22/E31 | F39: =F22/F31 | G39: =G22/G31 | H39: =H22/H31 | I39: =I22/I31
A40: Other Bets | B40: =B26/B31 | C40: =C26/C31 | D40: =D26/D31 | E40: =E26/E31 | F40: =F26/F31 | G40: =G26/G31 | H40: =H26/H31 | I40: =I26/I31
A43: 数据图例 Data Legend:
A44: 蓝色字体 Blue Font = 财报原始数据 Hardcoded from financials
A45: 绿色字体 Green Font = 链接自其他工作表 Links from other sheets
A46: 蓝底深蓝字体 Blue Fill = 可编辑假设 Editable assumption inputs
A47: 黄底粗体 Yellow Fill = 关键输出 Key output rows
A48: 黑色字体 Black Font = 公式计算 Calculated from formulas
A50: 数据来源 Data Sources:
A51: • Alphabet 2025 10-K Annual Report (filed Feb 4, 2026) - Consolidated Financial Statements pp.48-52
A52: • Alphabet 2025 10-K Note 15: Segment Information (Google Services, Cloud, Other Bets)
...

Sheet Segment_PL
A1: Segment P&L 分部利润表 (USD mm)
A2: Revenue / Costs / Operating Income by Division
B3: 2023 | C3: 2024 | D3: 2025 | E3: 2026E | F3: 2027E | G3: 2028E | H3: 2029E | I3: 2030E | K3: Notes / 预测逻辑
A5: Google Services 谷歌服务
A6: Revenue 收入 | B6: =Segment_Revenue!B19 | C6: =Segment_Revenue!C19 | D6: =Segment_Revenue!D19 | E6: =Segment_Revenue!E19 | F6: =Segment_Revenue!F19 | G6: =Segment_Revenue!G19 | H6: =Segment_Revenue!H19 | I6: =Segment_Revenue!I19 | K6: 链接自Segment_Revenue
A7: (-) Employee Comp 员工薪酬 | B7: 46224 | C7: 44560 | D7: 45124 | E7: =E6*Assumptions!$I$52 | F7: =F6*Assumptions!$I$52 | G7: =G6*Assumptions!$I$52 | H7: =H6*Assumptions!$I$52 | I7: =I6*Assumptions!$I$52 | K7: Revenue×Emp Comp%, 含SBC+福利 (Note 15)
A8: (-) Other Costs 其他费用 | B8: 130461 | C8: 139107 | D8: 158193 | E8: =E6*Assumptions!$I$53 | F8: =F6*Assumptions!$I$53 | G8: =G6*Assumptions!$I$53 | H8: =H6*Assumptions!$I$53 | I8: =I6*Assumptions!$I$53 | K8: 含TAC/内容采购/基础设施/设备成本
A9: Total Costs 总成本 | B9: =B7+B8 | C9: =C7+C8 | D9: =D7+D8 | E9: =E7+E8 | F9: =F7+F8 | G9: =G7+G8 | H9: =H7+H8 | I9: =I7+I8
A10: Operating Income 经营利润 | B10: =B6-B9 | C10: =C6-C9 | D10: =D6-D9 | E10: =E6-E9 | F10: =F6-F9 | G10: =G6-G9 | H10: =H6-H9 | I10: =I6-I9 | K10: Revenue-Total Costs
A11: Op Margin 经营利润率 | B11: =B10/B6 | C11: =C10/C6 | D11: =D10/D6 | E11: =E10/E6 | F11: =F10/F6 | G11: =G10/G6 | H11: =H10/H6 | I11: =I10/I6
A13: Google Cloud 谷歌云
A14: Revenue 收入 | B14: =Segment_Revenue!B22 | C14: =Segment_Revenue!C22 | D14: =Segment_Revenue!D22 | E14: =Segment_Revenue!E22 | F14: =Segment_Revenue!F22 | G14: =Segment_Revenue!G22 | H14: =Segment_Revenue!H22 | I14: =Segment_Revenue!I22 | K14: 链接自Segment_Revenue
A15: (-) Employee Comp 员工薪酬 | B15: 19054 | C15: 20519 | D15: 22078 | E15: =E14*Assumptions!$I$54 | F15: =F14*Assumptions!$I$54 | G15: =G14*Assumptions!$I$54 | H15: =H14*Assumptions!$I$54 | I15: =I14*Assumptions!$I$54 | K15: Revenue×Cloud Emp%, 人效持续改善
A16: (-) Other Costs 其他费用 | B16: 12318 | C16: 16598 | D16: 22717 | E16: =E14*Assumptions!$I$55 | F16: =F14*Assumptions!$I$55 | G16: =G14*Assumptions!$I$55 | H16: =H14*Assumptions!$I$55 | I16: =I14*Assumptions!$I$55 | K16: 含基础设施/第三方服务费
A17: Total Costs 总成本 | B17: =B15+B16 | C17: =C15+C16 | D17: =D15+D16 | E17: =E15+E16 | F17: =F15+F16 | G17: =G15+G16 | H17: =H15+H16 | I17: =I15+I16
A18: Operating Income 经营利润 | B18: =B14-B17 | C18: =C14-C17 | D18: =D14-D17 | E18: =E14-E17 | F18: =F14-F17 | G18: =G14-G17 | H18: =H14-H17 | I18: =I14-I17 | K18: Cloud利润率快速提升
A19: Op Margin 经营利润率 | B19: =B18/B14 | C19: =C18/C14 | D19: =D18/D14 | E19: =E18/E14 | F19: =F18/F14 | G19: =G18/G14 | H19: =H18/H14 | I19: =I18/I14
A21: Other Bets 其他创新业务
A22: Revenue 收入 | B22: =Segment_Revenue!B26 | C22: =Segment_Revenue!C26 | D22: =Segment_Revenue!D26 | E22: =Segment_Revenue!E26 | F22: =Segment_Revenue!F26 | G22: =Segment_Revenue!G26 | H22: =Segment_Revenue!H26 | I22: =Segment_Revenue!I26
A23: Operating Income (Loss) 经营利润(亏损) | B23: -4095 | C23: -4444 | D23: -7515 | E23: =E22*Assumptions!$I$56 | F23: =F22*Assumptions!$I$56 | G23: =G22*Assumptions!$I$56 | H23: =H22*Assumptions!$I$56 | I23: =I22*Assumptions!$I$56 | K23: Revenue×OI Margin%, 前沿业务持续亏损
A24: Implied Costs 隐含成本 (=Rev-OI) | B24: =B22-B23 | C24: =C22-C23 | D24: =D22-D23 | E24: =E22-E23 | F24: =F22-F23 | G24: =G22-G23 | H24: =H22-H23 | I24: =I22-I23
A25: Op Margin | B25: =B23/B22 | C25: =C23/C22 | D25: =D23/D22 | E25: =E23/E22 | F25: =F23/F22 | G25: =G23/G22 | H25: =H23/H22 | I25: =I23/I22
A27: Alphabet-level 未分配(AI研发+企业费用)
A28: Unallocated Costs 未分配费用 | B28: -9186 | C28: -10541 | D28: -16760 | E28: =-Assumptions!$I$57 | F28: =-Assumptions!$I$57 | G28: =-Assumptions!$I$57 | H28: =-Assumptions!$I$57 | I28: =-Assumptions!$I$57 | K28: 未分配AI研发+企业管理费用
A29: % of Total Revenue | B29: =B28/Segment_Revenue!B31 | C29: =C28/Segment_Revenue!C31 | D29: =D28/Segment_Revenue!D31 | E29: =E28/Segment_Revenue!E31 | F29: =F28/Segment_Revenue!F31 | G29: =G28/Segment_Revenue!G31 | H29: =H28/Segment_Revenue!H31 | I29: =I28/Segment_Revenue!I31
A31: Cross-Check 交叉验证: Sum of Segment OI vs Consolidated EBIT
A32: Sum of Segment OI 分部OI汇总 | B32: =B10+B18+B23+B28 | C32: =C10+C18+C23+C28 | D32: =D10+D18+D23+D28 | E32: =E10+E18+E23+E28 | F32: =F10+F18+F23+F28 | G32: =G10+G18+G23+G28 | H32: =H10+H18+H23+H28 | I32: =I10+I18+I23+I28 | K32: Services+Cloud+OtherBets+Alphabet-level
A33: Consolidated EBIT (from Consolidated_PL) | B33: =Consolidated_PL!B26 | C33: =Consolidated_PL!C26 | D33: =Consolidated_PL!D26 | E33: =Consolidated_PL!E26 | F33: =Consolidated_PL!F26 | G33: =Consolidated_PL!G26 | H33: =Consolidated_PL!H26 | I33: =Consolidated_PL!I26
A34: Difference 差异 (should = 0) | B34: =B32-B33 | C34: =C32-C33 | D34: =D32-D33 | E34: =E32-E33 | F34: =F32-F33 | G34: =G32-G33 | H34: =H32-H33 | I34: =I32-I33 | K34: 应为0，否则分部与合并口径不一致
A37: 数据图例 Data Legend:
A38: 蓝色字体 Blue Font = 财报原始数据 Hardcoded from financials
A39: 绿色字体 Green Font = 链接自其他工作表 Links from other sheets
A40: 蓝底深蓝字体 Blue Fill = 可编辑假设 Editable assumption inputs
A41: 黄底粗体 Yellow Fill = 关键输出 Key output rows
A42: 黑色字体 Black Font = 公式计算 Calculated from formulas
A44: 数据来源 Data Sources:
A45: • Alphabet 2025 10-K Annual Report (filed Feb 4, 2026) - Consolidated Financial Statements pp.48-52
A46: • Alphabet 2025 10-K Note 15: Segment Information (Google Services, Cloud, Other Bets)
A47: • Q4 2025 Earnings Call (Feb 4, 2026): CapEx 2026 guidance $75B (single quarter) → annualized ~$180B
A48: • 10Y UST yield ~4.2% (Feb 2026), Fed 2% long-term inflation target

Sheet Consolidated_PL
A1: Consolidated Income Statement 合并利润表 (USD mm)
A2: Source: 10-K p.49
B3: 2023 | C3: 2024 | D3: 2025 | E3: 2026E | F3: 2027E | G3: 2028E | H3: 2029E | I3: 2030E | K3: Notes / 预测逻辑
A5: Total Revenue 总收入 | B5: =Segment_Revenue!B31 | C5: =Segment_Revenue!C31 | D5: =Segment_Revenue!D31 | E5: =Segment_Revenue!E31 | F5: =Segment_Revenue!F31 | G5: =Segment_Revenue!G31 | H5: =Segment_Revenue!H31 | I5: =Segment_Revenue!I31 | K5: 链接自Segment_Revenue
A6: yoy % | C6: =C5/B5-1 | D6: =D5/C5-1 | E6: =E5/D5-1 | F6: =F5/E5-1 | G6: =G5/F5-1 | H6: =H5/G5-1 | I6: =I5/H5-1
A7: Google Advertising Rev (memo) 广告收入 | B7: =Segment_Revenue!B13 | C7: =Segment_Revenue!C13 | D7: =Segment_Revenue!D13 | E7: =Segment_Revenue!E13 | F7: =Segment_Revenue!F13 | G7: =Segment_Revenue!G13 | H7: =Segment_Revenue!H13 | I7: =Segment_Revenue!I13 | K7: 用于计算TAC
A9: Cost of Revenues 营业成本 (COGS)
A10: TAC 流量获取成本 | B10: 49316 | C10: 54900 | D10: 59926 | E10: =E7*Assumptions!$I$61 | F10: =F7*Assumptions!$I$61 | G10: =G7*Assumptions!$I$61 | H10: =H7*Assumptions!$I$61 | I10: =I7*Assumptions!$I$61 | K10: Ad Revenue×TAC Rate
A11: TAC rate (% of Ad Rev) | B11: =B10/B7 | C11: =C10/C7 | D11: =D10/D7 | E11: =E10/E7 | F11: =F10/F7 | G11: =G10/G7 | H11: =H10/H7 | I11: =I10/I7
A12: Other Cost of Revenues 其他营业成本 | B12: 84016 | C12: 91406 | D12: 102609 | E12: =E5*Assumptions!$I$62 | F12: =F5*Assumptions!$I$62 | G12: =G5*Assumptions!$I$62 | H12: =H5*Assumptions!$I$62 | I12: =I5*Assumptions!$I$62 | K12: 基础设施折旧/内容/数据中心运营
A13: Other COGS % | B13: =B12/B5 | C13: =C12/C5 | D13: =D12/D5 | E13: =E12/E5 | F13: =F12/F5 | G13: =G12/G5 | H13: =H12/H5 | I13: =I12/I5
A14: Total COGS 营业成本合计 | B14: =B10+B12 | C14: =C10+C12 | D14: =D10+D12 | E14: =E10+E12 | F14: =F10+F12 | G14: =G10+G12 | H14: =H10+H12 | I14: =I10+I12
A15: Gross Profit 毛利润 | B15: =B5-B14 | C15: =C5-C14 | D15: =D5-D14 | E15: =E5-E14 | F15: =F5-F14 | G15: =G5-G14 | H15: =H5-H14 | I15: =I5-I14 | K15: Revenue-COGS
A16: Gross Margin 毛利率 | B16: =B15/B5 | C16: =C15/C5 | D16: =D15/D5 | E16: =E15/E5 | F16: =F15/F5 | G16: =G15/G5 | H16: =H15/H5 | I16: =I15/I5
A18: Operating Expenses 营业费用 (OpEx)
A19: R&D 研发费用 | B19: 45427 | C19: 49326 | D19: 61087 | E19: =E5*Assumptions!$I$63 | F19: =F5*Assumptions!$I$63 | G19: =G5*Assumptions!$I$63 | H19: =H5*Assumptions!$I$63 | I19: =I5*Assumptions!$I$63 | K19: AI+Cloud持续投入，规模效应显现
A20: R&D 研发费用 % | B20: =B19/B5 | C20: =C19/C5 | D20: =D19/D5 | E20: =E19/E5 | F20: =F19/F5 | G20: =G19/G5 | H20: =H19/H5 | I20: =I19/I5
A21: S&M 销售与营销费用 | B21: 27917 | C21: 27808 | D21: 28693 | E21: =E5*Assumptions!$I$64 | F21: =F5*Assumptions!$I$64 | G21: =G5*Assumptions!$I$64 | H21: =H5*Assumptions!$I$64 | I21: =I5*Assumptions!$I$64 | K21: 效率提升，费率持续下降
A22: S&M 销售与营销费用 % | B22: =B21/B5 | C22: =C21/C5 | D22: =D21/D5 | E22: =E21/E5 | F22: =F21/F5 | G22: =G21/G5 | H22: =H21/H5 | I22: =I21/I5
A23: G&A 管理费用 (含一次性项目) | B23: 16425 | C23: 14188 | D23: 21482 | E23: =E5*Assumptions!$I$65 | F23: =F5*Assumptions!$I$65 | G23: =G5*Assumptions!$I$65 | H23: =H5*Assumptions!$I$65 | I23: =I5*Assumptions!$I$65 | K23: 2025含DOJ诉讼拨备，正常化后下降
A24: G&A 管理费用 % | B24: =B23/B5 | C24: =C23/C5 | D24: =D23/D5 | E24: =E23/E5 | F24: =F23/F5 | G24: =G23/G5 | H24: =H23/H5 | I24: =I23/I5
A25: Estimated Total OpEx (R&D+S&M+G&A) 营业费用合计 | B25: =B19+B21+B23 | C25: =C19+C21+C23 | D25: =D19+D21+D23 | E25: =E19+E21+E23 | F25: =F19+F21+F23 | G25: =G19+G21+G23 | H25: =H19+H21+H23 | I25: =I19+I21+I23 | K25: 参考性合计，EBIT由分部OI驱动
A26: EBIT 经营利润 (=Sum of Segment OI) | B26: =Segment_PL!B32 | C26: =Segment_PL!C32 | D26: =Segment_PL!D32 | E26: =Segment_PL!E32 | F26: =Segment_PL!F32 | G26: =Segment_PL!G32 | H26: =Segment_PL!H32 | I26: =Segment_PL!I32 | K26: 分部驱动：链接自Segment_PL汇总OI
A27: EBIT Margin 经营利润率 | B27: =B26/B5 | C27: =C26/C5 | D27: =D26/D5 | E27: =E26/E5 | F27: =F26/F5 | G27: =G26/G5 | H27: =H26/H5 | I27: =I26/I5
A28: Implied OpEx (=GP-EBIT) 隐含OpEx | B28: =B15-B26 | C28: =C15-C26 | D28: =D15-D26 | E28: =E15-E26 | F28: =F15-F26 | G28: =G15-G26 | H28: =H15-H26 | I28: =I15-I26
A30: OI&E 其他收入/(支出) | B30: 1424 | C30: 7425 | D30: 29787 | E30: 5000 | F30: 5500 | G30: 6000 | H30: 6500 | I30: 7000 | K30: 2025含$24B非上市证券估值收益(一次性)
A31: Pre-tax Income 税前利润 | B31: =B26+B30 | C31: =C26+C30 | D31: =D26+D30 | E31: =E26+E30 | F31: =F26+F30 | G31: =G26+G30 | H31: =H26+H30 | I31: =I26+I30
A32: Income Tax 所得税 | B32: 11922 | C32: 19697 | D32: 26656 | E32: =E31*Assumptions!$I$11 | F32: =F31*Assumptions!$I$11 | G32: =G31*Assumptions!$I$11 | H32: =H31*Assumptions!$I$11 | I32: =I31*Assumptions!$I$11 | K32: Pre-tax Income×ETR
A33: Net Income 净利润 | B33: =B31-B32 | C33: =C31-C32 | D33: =D31-D32 | E33: =E31-E32 | F33: =F31-F32 | G33: =G31-G32 | H33: =H31-H32 | I33: =I31-I32 | K33: Pre-tax - Tax
A34: Net Margin 净利率 | B34: =B33/B5 | C34: =C33/C5 | D34: =D33/D5 | E34: =E33/E5 | F34: =F33/F5 | G34: =G33/G5 | H34: =H33/H5 | I34: =I33/I5
A35: NI yoy % | C35: =C33/B33-1 | D35: =D33/C33-1 | E35: =E33/D33-1 | F35: =F33/E33-1 | G35: =G33/F33-1 | H35: =H33/G33-1 | I35: =I33/H33-1
A37: D&A 折旧与摊销 (memo) | B37: 11946 | C37: 15311 | D37: 21136 | E37: =E5*Assumptions!$I$66 | F37: =F5*Assumptions!$I$66 | G37: =G5*Assumptions!$I$66 | H37: =H5*Assumptions!$I$66 | I37: =I5*Assumptions!$I$66 | K37: CapEx高增长→D&A占比上升
A38: SBC 股权激励 (memo) | B38: 22460 | C38: 22785 | D38: 24953 | E38: =E5*Assumptions!$I$67 | F38: =F5*Assumptions!$I$67 | G38: =G5*Assumptions!$I$67 | H38: =H5*Assumptions!$I$67 | I38: =I5*Assumptions!$I$67 | K38: SBC占比逐步下降
A40: Diluted Shares 稀释股数 (mm) | B40: 12722 | C40: 12447 | D40: 12230 | E40: =D40*0.98 | F40: =E40*0.98 | G40: =F40*0.98 | H40: =G40*0.98 | I40: =H40*0.98 | K40: 年回购~2%股本
A41: Diluted EPS 稀释每股收益 | B41: =B33/B40 | C41: =C33/C40 | D41: =D33/D40 | E41: =E33/E40 | F41: =F33/F40 | G41: =G33/G40 | H41: =H33/H40 | I41: =I33/I40 | K41: Net Income / Diluted Shares
A44: 数据图例 Data Legend:
A45: 蓝色字体 Blue Font = 财报原始数据 Hardcoded from financials
A46: 绿色字体 Green Font = 链接自其他工作表 Links from other sheets
A47: 蓝底深蓝字体 Blue Fill = 可编辑假设 Editable assumption inputs
A48: 黄底粗体 Yellow Fill = 关键输出 Key output rows
...

Sheet BS
A1: Consolidated Balance Sheet 合并资产负债表 (USD mm)
A2: Source: 10-K p.48 | 2023 estimated from prior filing
B3: 2023 | C3: 2024 | D3: 2025 | E3: 2026E | F3: 2027E | G3: 2028E | H3: 2029E | I3: 2030E | K3: Notes / 预测逻辑
A5: Current Assets 流动资产
A6: Cash & Equivalents 现金 | B6: 24048 | C6: 23466 | D6: 30708 | E6: =Cash_Flow!E47 | F6: =Cash_Flow!F47 | G6: =Cash_Flow!G47 | H6: =Cash_Flow!H47 | I6: =Cash_Flow!I47 | K6: 链接自CF期末现金(forecast)
A7: Marketable Securities 有价证券 | B7: 86868 | C7: 72191 | D7: 96135 | E7: =D7*(1+Assumptions!$I$92) | F7: =E7*(1+Assumptions!$I$92) | G7: =F7*(1+Assumptions!$I$92) | H7: =G7*(1+Assumptions!$I$92) | I7: =H7*(1+Assumptions!$I$92) | K7: 投资组合，假设温和增长
A8: Total Cash & Securities 现金合计 | B8: 110916 | C8: 95657 | D8: 126843 | E8: =E6+E7 | F8: =F6+F7 | G8: =G6+G7 | H8: =H6+H7 | I8: =I6+I7 | K8: Cash+Securities
A9: Accounts Receivable, net 应收账款 | B9: 40300 | C9: 52340 | D9: 62886 | E9: =Consolidated_PL!E5*Assumptions!$I$84/365 | F9: =Consolidated_PL!F5*Assumptions!$I$84/365 | G9: =Consolidated_PL!G5*Assumptions!$I$84/365 | H9: =Consolidated_PL!H5*Assumptions!$I$84/365 | I9: =Consolidated_PL!I5*Assumptions!$I$84/365 | K9: Revenue×AR Days/365
A10: Other Current Assets 其他流动资产 | B10: 12200 | C10: 15714 | D10: 16309 | E10: =Consolidated_PL!E5*0.04 | F10: =Consolidated_PL!F5*0.04 | G10: =Consolidated_PL!G5*0.04 | H10: =Consolidated_PL!H5*0.04 | I10: =Consolidated_PL!I5*0.04 | K10: 预付/库存/其他
A11: Total Current Assets 流动资产合计 | B11: =B8+B9+B10 | C11: =C8+C9+C10 | D11: =D8+D9+D10 | E11: =E8+E9+E10 | F11: =F8+F9+F10 | G11: =G8+G9+G10 | H11: =H8+H9+H10 | I11: =I8+I9+I10
A13: Non-Current Assets 非流动资产
A14: Non-marketable Securities 非上市证券 | B14: 31008 | C14: 37982 | D14: 68687 | E14: =D14*(1+Assumptions!$I$91) | F14: =E14*(1+Assumptions!$I$91) | G14: =F14*(1+Assumptions!$I$91) | H14: =G14*(1+Assumptions!$I$91) | I14: =H14*(1+Assumptions!$I$91) | K14: 含私募股权投资
A15: Deferred Income Taxes 递延所得税 | B15: 12270 | C15: 17180 | D15: 9113 | E15: 9000 | F15: 9000 | G15: 9000 | H15: 9000 | I15: 9000
A16: PP&E, net 固定资产净值 | B16: 134345 | C16: 171036 | D16: 246597 | E16: =D16+Assumptions!$I$72-Consolidated_PL!E37 | F16: =E16+Assumptions!$I$73-Consolidated_PL!F37 | G16: =F16+Assumptions!$I$74-Consolidated_PL!G37 | H16: =G16+Assumptions!$I$75-Consolidated_PL!H37 | I16: =H16+Assumptions!$I$76-Consolidated_PL!I37 | K16: Prior+CapEx-D&A
A17: Operating Lease Assets 经营租赁 | B17: 14253 | C17: 13588 | D17: 15221 | E17: =D17*(1+Assumptions!$I$90) | F17: =E17*(1+Assumptions!$I$90) | G17: =F17*(1+Assumptions!$I$90) | H17: =G17*(1+Assumptions!$I$90) | I17: =H17*(1+Assumptions!$I$90) | K17: 办公/数据中心租赁
A18: Goodwill 商誉 | B18: 29198 | C18: 31885 | D18: 33380 | E18: =D18*1.02 | F18: =E18*1.02 | G18: =F18*1.02 | H18: =G18*1.02 | I18: =H18*1.02 | K18: 收购溢价
A19: Other Non-current 其他非流动 | B19: 16902 | C19: 14874 | D19: 16245 | E19: =D19*1.03 | F19: =E19*1.03 | G19: =F19*1.03 | H19: =G19*1.03 | I19: =H19*1.03 | K19: 无形资产/其他
A20: Total Non-Current Assets 非流动资产合计 | B20: =B14+B15+B16+B17+B18+B19 | C20: =C14+C15+C16+C17+C18+C19 | D20: =D14+D15+D16+D17+D18+D19 | E20: =E14+E15+E16+E17+E18+E19 | F20: =F14+F15+F16+F17+F18+F19 | G20: =G14+G15+G16+G17+G18+G19 | H20: =H14+H15+H16+H17+H18+H19 | I20: =I14+I15+I16+I17+I18+I19
A21: TOTAL ASSETS 资产合计 | B21: =B11+B20 | C21: =C11+C20 | D21: =D11+D20 | E21: =E11+E20 | F21: =F11+F20 | G21: =G11+G20 | H21: =H11+H20 | I21: =I11+I20
A23: Current Liabilities 流动负债
A24: Accounts Payable 应付账款 | B24: 7100 | C24: 7987 | D24: 12200 | E24: =Consolidated_PL!E14*Assumptions!$I$85/365 | F24: =Consolidated_PL!F14*Assumptions!$I$85/365 | G24: =Consolidated_PL!G14*Assumptions!$I$85/365 | H24: =Consolidated_PL!H14*Assumptions!$I$85/365 | I24: =Consolidated_PL!I14*Assumptions!$I$85/365 | K24: COGS×AP Days/365
A25: Accrued Compensation 应计薪酬 | B25: 14200 | C25: 15069 | D25: 17546 | E25: =Consolidated_PL!E5*Assumptions!$I$86 | F25: =Consolidated_PL!F5*Assumptions!$I$86 | G25: =Consolidated_PL!G5*Assumptions!$I$86 | H25: =Consolidated_PL!H5*Assumptions!$I$86 | I25: =Consolidated_PL!I5*Assumptions!$I$86 | K25: Revenue×AccComp%
A26: Accrued Expenses 应计费用 | B26: 43000 | C26: 51228 | D26: 55557 | E26: =Consolidated_PL!E5*Assumptions!$I$87 | F26: =Consolidated_PL!F5*Assumptions!$I$87 | G26: =Consolidated_PL!G5*Assumptions!$I$87 | H26: =Consolidated_PL!H5*Assumptions!$I$87 | I26: =Consolidated_PL!I5*Assumptions!$I$87 | K26: Revenue×AccExp%
A27: Accrued Revenue Share 应计收入分成 | B27: 8743 | C27: 9802 | D27: 10864 | E27: =Segment_Revenue!E13*Assumptions!$I$88 | F27: =Segment_Revenue!F13*Assumptions!$I$88 | G27: =Segment_Revenue!G13*Assumptions!$I$88 | H27: =Segment_Revenue!H13*Assumptions!$I$88 | I27: =Segment_Revenue!I13*Assumptions!$I$88 | K27: Ad Revenue×RevShare%
A28: Deferred Revenue 递延收入 | B28: 3993 | C28: 5036 | D28: 6578 | E28: =D28*(1+Assumptions!$I$89) | F28: =E28*(1+Assumptions!$I$89) | G28: =F28*(1+Assumptions!$I$89) | H28: =G28*(1+Assumptions!$I$89) | I28: =H28*(1+Assumptions!$I$89) | K28: Cloud预付合同增长
A29: Total Current Liabilities 流动负债合计 | B29: =B24+B25+B26+B27+B28 | C29: =C24+C25+C26+C27+C28 | D29: =D24+D25+D26+D27+D28 | E29: =E24+E25+E26+E27+E28 | F29: =F24+F25+F26+F27+F28 | G29: =G24+G25+G26+G27+G28 | H29: =H24+H25+H26+H27+H28 | I29: =I24+I25+I26+I27+I28
A31: Non-Current Liabilities 非流动负债
A32: Long-term Debt 长期债务 | B32: 12887 | C32: 10883 | D32: 46547 | E32: =D32+Assumptions!$I$97 | F32: =E32+Assumptions!$I$98 | G32: =F32+Assumptions!$I$99 | H32: =G32+Assumptions!$I$100 | I32: =H32+Assumptions!$I$101 | K32: 2025发行$65B新债
A33: Income Taxes Payable, NC 长期应交税 | B33: 8049 | C33: 8782 | D33: 9531 | E33: =D33*1.03 | F33: =E33*1.03 | G33: =F33*1.03 | H33: =G33*1.03 | I33: =H33*1.03
A34: Operating Lease Liabilities 经营租赁负债 | B34: 10989 | C34: 11691 | D34: 12744 | E34: =E17*0.84 | F34: =F17*0.84 | G34: =G17*0.84 | H34: =H17*0.84 | I34: =I17*0.84 | K34: 跟踪ROU资产
A35: Other Long-term 其他长期负债 | B35: 9052 | C35: 4694 | D35: 8449 | E35: =D35*1.05 | F35: =E35*1.05 | G35: =F35*1.05 | H35: =G35*1.05 | I35: =H35*1.05
A36: Total Non-Current Liabilities 非流动负债 | B36: =B32+B33+B34+B35 | C36: =C32+C33+C34+C35 | D36: =D32+D33+D34+D35 | E36: =E32+E33+E34+E35 | F36: =F32+F33+F34+F35 | G36: =G32+G33+G34+G35 | H36: =H32+H33+H34+H35 | I36: =I32+I33+I34+I35
A37: TOTAL LIABILITIES 负债合计 | B37: =B29+B36 | C37: =C29+C36 | D37: =D29+D36 | E37: =E29+E36 | F37: =F29+F36 | G37: =G29+G36 | H37: =H29+H36 | I37: =I29+I36
A39: Stockholders' Equity 股东权益
A40: Total Equity 股东权益合计 | B40: 283379 | C40: 325084 | D40: 415265 | E40: =D40+Consolidated_PL!E33-Assumptions!$I$79-Assumptions!$I$80*Consolidated_PL!E40+Consolidated_PL!E38*(1-Assumptions!$I$93) | F40: =E40+Consolidated_PL!F33-Assumptions!$I$79-Assumptions!$I$80*Consolidated_PL!F40+Consolidated_PL!F38*(1-Assumptions!$I$93) | G40: =F40+Consolidated_PL!G33-Assumptions!$I$79-Assumptions!$I$80*Consolidated_PL!G40+Consolidated_PL!G38*(1-Assumptions!$I$93) | H40: =G40+Consolidated_PL!H33-Assumptions!$I$79-Assumptions!$I$80*Consolidated_PL!H40+Consolidated_PL!H38*(1-Assumptions!$I$93) | I40: =H40+Consolidated_PL!I33-Assumptions!$I$79-Assumptions!$I$80*Consolidated_PL!I40+Consolidated_PL!I38*(1-Assumptions!$I$93) | K40: Prior+NI-Buyback-Div+SBC×(1-结算率)
A42: TOTAL LIABILITIES & EQUITY 负债+权益 | B42: =B37+B40 | C42: =C37+C40 | D42: =D37+D40 | E42: =E37+E40 | F42: =F37+F40 | G42: =G37+G40 | H42: =H37+H40 | I42: =I37+I40
A43: Balance Check 平衡检验 (Assets - L&E) | B43: =B21-B42 | C43: =C21-C42 | D43: =D21-D42 | E43: =E21-E42 | F43: =F21-F42 | G43: =G21-G42 | H43: =H21-H42 | I43: =I21-I42 | K43: 应为0 (Cash为plug项)
A46: 数据图例 Data Legend:
A47: 蓝色字体 Blue Font = 财报原始数据 Hardcoded from financials
A48: 绿色字体 Green Font = 链接自其他工作表 Links from other sheets
...

Sheet Cash_Flow
A1: Cash Flow Statement 现金流量表 (USD mm)
A2: 三表联动: Ending Cash → BS!Cash | Source: 10-K pp.51-52
B3: 2023 | C3: 2024 | D3: 2025 | E3: 2026E | F3: 2027E | G3: 2028E | H3: 2029E | I3: 2030E | K3: Notes / 预测逻辑
A5: Operating Activities 经营活动现金流
A6: Net Income 净利润 | B6: 73795 | C6: 100118 | D6: 132170 | E6: =Consolidated_PL!E33 | F6: =Consolidated_PL!F33 | G6: =Consolidated_PL!G33 | H6: =Consolidated_PL!H33 | I6: =Consolidated_PL!I33 | K6: 链接自Consolidated_PL
A7: (+) D&A 折旧与摊销 | B7: 11946 | C7: 15311 | D7: 21136 | E7: =Consolidated_PL!E37 | F7: =Consolidated_PL!F37 | G7: =Consolidated_PL!G37 | H7: =Consolidated_PL!H37 | I7: =Consolidated_PL!I37 | K7: 非现金项目加回
A8: (+) SBC 股权激励 | B8: 22460 | C8: 22785 | D8: 24953 | E8: =Consolidated_PL!E38 | F8: =Consolidated_PL!F38 | G8: =Consolidated_PL!G38 | H8: =Consolidated_PL!H38 | I8: =Consolidated_PL!I38 | K8: 非现金项目加回
A9: Non-cash & Accrual Adjustments 非现金及应计调整
A10: Deferred Tax 递延所得税 | B10: -7763 | C10: -5257 | D10: 8348 | E10: =-(BS!E15-BS!D15) | F10: =-(BS!F15-BS!E15) | G10: =-(BS!G15-BS!F15) | H10: =-(BS!H15-BS!G15) | I10: =-(BS!I15-BS!H15) | K10: DTA减少=现金来源(链接BS)
A11: OpLease Net Adj 经营租赁净调整 | B11: 0 | C11: 0 | D11: 0 | E11: =(BS!E34-BS!D34)-(BS!E17-BS!D17) | F11: =(BS!F34-BS!E34)-(BS!F17-BS!E17) | G11: =(BS!G34-BS!F34)-(BS!G17-BS!F17) | H11: =(BS!H34-BS!G34)-(BS!H17-BS!G17) | I11: =(BS!I34-BS!H34)-(BS!I17-BS!H17) | K11: Δ租赁负债-Δ租赁资产
A12: LT Tax Payable Chg 长期应交税 | B12: 0 | C12: 0 | D12: 0 | E12: =BS!E33-BS!D33 | F12: =BS!F33-BS!E33 | G12: =BS!G33-BS!F33 | H12: =BS!H33-BS!G33 | I12: =BS!I33-BS!H33 | K12: 长期税负增加=现金来源
A13: Other LT Liab Chg 其他长期负债 | B13: 0 | C13: 0 | D13: 0 | E13: =BS!E35-BS!D35 | F13: =BS!F35-BS!E35 | G13: =BS!G35-BS!F35 | H13: =BS!H35-BS!G35 | I13: =BS!I35-BS!H35 | K13: 其他长期负债变动
A14: Securities G/L + Other 证券损益+其他 | B14: 5153 | C14: 748 | D14: -22512 | E14: 0 | F14: 0 | G14: 0 | H14: 0 | I14: 0 | K14: 2025含$24.6B证券损益(一次性)
A15: Working Capital Changes 营运资金变动 (→ BS)
A16: Chg AR 应收变动 | B16: -7833 | C16: -5891 | D16: -8779 | E16: =-(BS!E9-BS!D9) | F16: =-(BS!F9-BS!E9) | G16: =-(BS!G9-BS!F9) | H16: =-(BS!H9-BS!G9) | I16: =-(BS!I9-BS!H9) | K16: 应收增加=现金流出
A17: Chg AccComp 应计薪酬变动 | B17: 0 | C17: 0 | D17: 0 | E17: =(BS!E25-BS!D25) | F17: =(BS!F25-BS!E25) | G17: =(BS!G25-BS!F25) | H17: =(BS!H25-BS!G25) | I17: =(BS!I25-BS!H25) | K17: 薪酬负债增加=现金留存(历史含在AccExp中)
A18: Chg OtherCA 其他流动资产 | B18: -2143 | C18: -1397 | D18: -4542 | E18: =-(BS!E10-BS!D10) | F18: =-(BS!F10-BS!E10) | G18: =-(BS!G10-BS!F10) | H18: =-(BS!H10-BS!G10) | I18: =-(BS!I10-BS!H10) | K18: 其他流动资产增加=现金流出
A19: Chg AP 应付变动 | B19: 664 | C19: 359 | D19: 907 | E19: =(BS!E24-BS!D24) | F19: =(BS!F24-BS!E24) | G19: =(BS!G24-BS!F24) | H19: =(BS!H24-BS!G24) | I19: =(BS!I24-BS!H24) | K19: 应付增加=现金留存
A20: Chg AccExp 应计费用变动 | B20: 3937 | C20: -1161 | D20: 12939 | E20: =(BS!E26-BS!D26) | F20: =(BS!F26-BS!E26) | G20: =(BS!G26-BS!F26) | H20: =(BS!H26-BS!G26) | I20: =(BS!I26-BS!H26) | K20: 运营应计增加=现金留存
A21: Chg RevShare 收入分成变动 | B21: 482 | C21: 1059 | D21: 899 | E21: =(BS!E27-BS!D27) | F21: =(BS!F27-BS!E27) | G21: =(BS!G27-BS!F27) | H21: =(BS!H27-BS!G27) | I21: =(BS!I27-BS!H27) | K21: 分成负债增加=现金留存
A22: Chg DefRev 递延收入变动 | B22: 525 | C22: 1043 | D22: 2420 | E22: =(BS!E28-BS!D28) | F22: =(BS!F28-BS!E28) | G22: =(BS!G28-BS!F28) | H22: =(BS!H28-BS!G28) | I22: =(BS!I28-BS!H28) | K22: 预收增加=现金留存
A23: CFO 经营活动净现金 | B23: 101746 | C23: 125299 | D23: 164713 | E23: =E6+E7+E8+E10+E11+E12+E13+E14+E16+E17+E18+E19+E20+E21+E22 | F23: =F6+F7+F8+F10+F11+F12+F13+F14+F16+F17+F18+F19+F20+F21+F22 | G23: =G6+G7+G8+G10+G11+G12+G13+G14+G16+G17+G18+G19+G20+G21+G22 | H23: =H6+H7+H8+H10+H11+H12+H13+H14+H16+H17+H18+H19+H20+H21+H22 | I23: =I6+I7+I8+I10+I11+I12+I13+I14+I16+I17+I18+I19+I20+I21+I22 | K23: NI+D&A+SBC+非现金调整+WC变动
A25: Investing Activities 投资活动
A26: CapEx 资本支出 | B26: -32251 | C26: -52535 | D26: -91447 | E26: =-Assumptions!$I$72 | F26: =-Assumptions!$I$73 | G26: =-Assumptions!$I$74 | H26: =-Assumptions!$I$75 | I26: =-Assumptions!$I$76 | K26: 2026=$180B per mgmt guidance
A27: CapEx / Revenue | B27: =-B26/Consolidated_PL!B5 | C27: =-C26/Consolidated_PL!C5 | D27: =-D26/Consolidated_PL!D5 | E27: =-E26/Consolidated_PL!E5 | F27: =-F26/Consolidated_PL!F5 | G27: =-G26/Consolidated_PL!G5 | H27: =-H26/Consolidated_PL!H5 | I27: =-I26/Consolidated_PL!I5
A28: Chg NonMkt Securities 非上市证券 | B28: -3626 | C28: -9750 | D28: -8311 | E28: =-(BS!E14-BS!D14) | F28: =-(BS!F14-BS!E14) | G28: =-(BS!G14-BS!F14) | H28: =-(BS!H14-BS!G14) | I28: =-(BS!I14-BS!H14) | K28: 非上市证券净投资(增加为负)
A29: Acquisitions 收购 (Goodwill) | B29: 0 | C29: 0 | D29: 0 | E29: =-(BS!E18-BS!D18) | F29: =-(BS!F18-BS!E18) | G29: =-(BS!G18-BS!F18) | H29: =-(BS!H18-BS!G18) | I29: =-(BS!I18-BS!H18) | K29: 商誉增加=并购现金流出
A30: Other Investing 其他投资 | B30: 0 | C30: 0 | D30: 0 | E30: =-(BS!E19-BS!D19) | F30: =-(BS!F19-BS!E19) | G30: =-(BS!G19-BS!F19) | H30: =-(BS!H19-BS!G19) | I30: =-(BS!I19-BS!H19) | K30: 无形资产/其他非流动
A31: Net MktSec Activity 有价证券净投资 | B31: 8814 | C31: 16749 | D31: -20533 | E31: =-(BS!E7-BS!D7) | F31: =-(BS!F7-BS!E7) | G31: =-(BS!G7-BS!F7) | H31: =-(BS!H7-BS!G7) | I31: =-(BS!I7-BS!H7) | K31: 有价证券增加=现金流出(Base=0)
A32: CFI 投资活动净现金 | B32: -27063 | C32: -45536 | D32: -120291 | E32: =E26+E28+E29+E30+E31 | F32: =F26+F28+F29+F30+F31 | G32: =G26+G28+G29+G30+G31 | H32: =H26+H28+H29+H30+H31 | I32: =I26+I28+I29+I30+I31 | K32: CapEx+证券+收购+其他
A34: FCF 自由现金流 (=CFO+CapEx) | B34: =B23+B26 | C34: =C23+C26 | D34: =D23+D26 | E34: =E23+E26 | F34: =F23+F26 | G34: =G23+G26 | H34: =H23+H26 | I34: =I23+I26 | K34: CFO-|CapEx| (资本配置前)
A35: FCF Margin 自由现金流率 | B35: =B34/Consolidated_PL!B5 | C35: =C34/Consolidated_PL!C5 | D35: =D34/Consolidated_PL!D5 | E35: =E34/Consolidated_PL!E5 | F35: =F34/Consolidated_PL!F5 | G35: =G34/Consolidated_PL!G5 | H35: =H34/Consolidated_PL!H5 | I35: =I34/Consolidated_PL!I5
A37: Financing Activities 融资活动
A38: Share Repurchases 股份回购 | B38: -61504 | C38: -62222 | D38: -45709 | E38: =-Assumptions!$I$79 | F38: =-Assumptions!$I$79 | G38: =-Assumptions!$I$79 | H38: =-Assumptions!$I$79 | I38: =-Assumptions!$I$79 | K38: 链接自Assumptions回购假设
A39: Dividends Paid 股息支付 | B39: 0 | C39: -7363 | D39: -10049 | E39: =-Assumptions!$I$80*Consolidated_PL!E40 | F39: =-Assumptions!$I$80*Consolidated_PL!F40 | G39: =-Assumptions!$I$80*Consolidated_PL!G40 | H39: =-Assumptions!$I$80*Consolidated_PL!H40 | I39: =-Assumptions!$I$80*Consolidated_PL!I40 | K39: -DPS×稀释股数
A40: Stock Net Settlement 股权净结算 | B40: -9837 | C40: -12190 | D40: -14167 | E40: =-Consolidated_PL!E38*Assumptions!$I$93 | F40: =-Consolidated_PL!F38*Assumptions!$I$93 | G40: =-Consolidated_PL!G38*Assumptions!$I$93 | H40: =-Consolidated_PL!H38*Assumptions!$I$93 | I40: =-Consolidated_PL!I38*Assumptions!$I$93 | K40: -SBC×结算率(RSU税代扣)
A41: Net Debt Issuance 净债务融资 | B41: -760 | C41: 888 | D41: 32137 | E41: =Assumptions!$I$97 | F41: =Assumptions!$I$98 | G41: =Assumptions!$I$99 | H41: =Assumptions!$I$100 | I41: =Assumptions!$I$101 | K41: 链接自Assumptions融资计划
A42: CFF 融资活动净现金 | B42: -72093 | C42: -79733 | D42: -37388 | E42: =E38+E39+E40+E41 | F42: =F38+F39+F40+F41 | G42: =G38+G39+G40+G41 | H42: =H38+H39+H40+H41 | I42: =I38+I39+I40+I41 | K42: 回购+股息+股权结算+净融资
A44: Cash Reconciliation 现金勾稽 (→ BS!Cash)
A45: Net Change in Cash 现金净变动 | B45: =B23+B32+B42 | C45: =C23+C32+C42 | D45: =D23+D32+D42 | E45: =E23+E32+E42 | F45: =F23+F32+F42 | G45: =G23+G32+G42 | H45: =H23+H32+H42 | I45: =I23+I32+I42 | K45: CFO+CFI+CFF
...

Sheet DCF
A1: DCF Valuation DCF估值 (USD mm)
A2: CapEx 2026 = $180B per mgmt guidance
B4: 2026E | C4: 2027E | D4: 2028E | E4: 2029E | F4: 2030E | G4: Notes / 预测逻辑
A6: EBIT 经营利润 | B6: =Consolidated_PL!E26 | C6: =Consolidated_PL!F26 | D6: =Consolidated_PL!G26 | E6: =Consolidated_PL!H26 | F6: =Consolidated_PL!I26 | G6: 链接自Consolidated_PL
A7: (-) Tax on EBIT EBIT税负 | B7: =B6*Assumptions!$I$11 | C7: =C6*Assumptions!$I$11 | D7: =D6*Assumptions!$I$11 | E7: =E6*Assumptions!$I$11 | F7: =F6*Assumptions!$I$11
A8: NOPAT 税后净营业利润 | B8: =B6-B7 | C8: =C6-C7 | D8: =D6-D7 | E8: =E6-E7 | F8: =F6-F7 | G8: EBIT×(1-Tax Rate)
A9: (+) D&A 折旧摊销 | B9: =Consolidated_PL!E37 | C9: =Consolidated_PL!F37 | D9: =Consolidated_PL!G37 | E9: =Consolidated_PL!H37 | F9: =Consolidated_PL!I37
A10: (-) CapEx 资本支出 | B10: =Assumptions!$I$72 | C10: =Assumptions!$I$73 | D10: =Assumptions!$I$74 | E10: =Assumptions!$I$75 | F10: =Assumptions!$I$76 | G10: 2026=$180B management guidance
A11: (-) Change in NWC 净营运资本变动 | B11: =(Consolidated_PL!E5-Consolidated_PL!D5)*Assumptions!$I$68 | C11: =(Consolidated_PL!F5-Consolidated_PL!E5)*Assumptions!$I$68 | D11: =(Consolidated_PL!G5-Consolidated_PL!F5)*Assumptions!$I$68 | E11: =(Consolidated_PL!H5-Consolidated_PL!G5)*Assumptions!$I$68 | F11: =(Consolidated_PL!I5-Consolidated_PL!H5)*Assumptions!$I$68
A12: UFCF 无杠杆自由现金流 | B12: =B8+B9-B10-B11 | C12: =C8+C9-C10-C11 | D12: =D8+D9-D10-D11 | E12: =E8+E9-E10-E11 | F12: =F8+F9-F10-F11 | G12: NOPAT+D&A-CapEx-ΔNWC
A13: Discount Factor 折现因子 | B13: =1/(1+Assumptions!$I$18)^1 | C13: =1/(1+Assumptions!$I$18)^2 | D13: =1/(1+Assumptions!$I$18)^3 | E13: =1/(1+Assumptions!$I$18)^4 | F13: =1/(1+Assumptions!$I$18)^5
A14: PV of UFCF UFCF现值 | B14: =B12*B13 | C14: =C12*C13 | D14: =D12*D13 | E14: =E12*E13 | F14: =F12*F13
A16: TV 终值 (Gordon Growth Model) | B16: =F12*(1+Assumptions!$I$13)/(Assumptions!$I$18-Assumptions!$I$13) | G16: UFCF₂₀₃₀×(1+g)/(WACC-g)
A17: PV of TV 终值现值 | B17: =B16*F13
A18: TV as % of EV TV占比 | B18: =B17/(SUM(B14:F14)+B17)
A20: Sum of PV of UFCF UFCF现值合计 | B20: =SUM(B14:F14) | G20: 5年UFCF折现合计
A21: PV of TV 终值现值 | B21: =B17
A22: EV 企业价值 | B22: =B20+B21 | G22: =UFCF PV + TV PV
A23: (+) Cash & Securities 加回现金 | B23: =Assumptions!$I$21 | G23: 年末现金+有价证券
A24: (-) Total Debt 减去债务 | B24: =Assumptions!$I$22 | G24: 短期+长期债务
A25: Equity Value 股权价值 | B25: =B22+B23-B24 | G25: =EV+Cash-Debt
A26: Diluted Shares 稀释股数 (mm) | B26: =Assumptions!$I$23
A27: Implied Share Price 隐含股价 | B27: =B25/B26 | G27: =Equity Value / Shares
A31: 数据图例 Data Legend:
A32: 蓝色字体 Blue Font = 财报原始数据 Hardcoded from financials
A33: 绿色字体 Green Font = 链接自其他工作表 Links from other sheets
A34: 蓝底深蓝字体 Blue Fill = 可编辑假设 Editable assumption inputs
A35: 黄底粗体 Yellow Fill = 关键输出 Key output rows
A36: 黑色字体 Black Font = 公式计算 Calculated from formulas
A38: 数据来源 Data Sources:
A39: • Alphabet 2025 10-K Annual Report (filed Feb 4, 2026) - Consolidated Financial Statements pp.48-52
A40: • Alphabet 2025 10-K Note 15: Segment Information (Google Services, Cloud, Other Bets)
A41: • Q4 2025 Earnings Call (Feb 4, 2026): CapEx 2026 guidance $75B (single quarter) → annualized ~$180B
A42: • 10Y UST yield ~4.2% (Feb 2026), Fed 2% long-term inflation target

Sheet Sensitivity
A1: Sensitivity 敏感性分析 - Implied Share Price (USD)
A2: WACC 加权平均资本成本 × g 永续增长率
A4: g \ WACC | B4: 0.075 | C4: 0.08 | D4: 0.085 | E4: 0.09 | F4: 0.095 | G4: 0.1 | H4: 0.105
A5: 0.02 | B5: =(SUM(DCF!B14:F14)+(DCF!F12*(1+$A5)/(B$4-$A5))/((1+B$4)^5)+Assumptions!$I$21-Assumptions!$I$22)/Assumptions!$I$23 | C5: =(SUM(DCF!B14:F14)+(DCF!F12*(1+$A5)/(C$4-$A5))/((1+C$4)^5)+Assumptions!$I$21-Assumptions!$I$22)/Assumptions!$I$23 | D5: =(SUM(DCF!B14:F14)+(DCF!F12*(1+$A5)/(D$4-$A5))/((1+D$4)^5)+Assumptions!$I$21-Assumptions!$I$22)/Assumptions!$I$23 | E5: =(SUM(DCF!B14:F14)+(DCF!F12*(1+$A5)/(E$4-$A5))/((1+E$4)^5)+Assumptions!$I$21-Assumptions!$I$22)/Assumptions!$I$23 | F5: =(SUM(DCF!B14:F14)+(DCF!F12*(1+$A5)/(F$4-$A5))/((1+F$4)^5)+Assumptions!$I$21-Assumptions!$I$22)/Assumptions!$I$23 | G5: =(SUM(DCF!B14:F14)+(DCF!F12*(1+$A5)/(G$4-$A5))/((1+G$4)^5)+Assumptions!$I$21-Assumptions!$I$22)/Assumptions!$I$23 | H5: =(SUM(DCF!B14:F14)+(DCF!F12*(1+$A5)/(H$4-$A5))/((1+H$4)^5)+Assumptions!$I$21-Assumptions!$I$22)/Assumptions!$I$23
A6: 0.025 | B6: =(SUM(DCF!B14:F14)+(DCF!F12*(1+$A6)/(B$4-$A6))/((1+B$4)^5)+Assumptions!$I$21-Assumptions!$I$22)/Assumptions!$I$23 | C6: =(SUM(DCF!B14:F14)+(DCF!F12*(1+$A6)/(C$4-$A6))/((1+C$4)^5)+Assumptions!$I$21-Assumptions!$I$22)/Assumptions!$I$23 | D6: =(SUM(DCF!B14:F14)+(DCF!F12*(1+$A6)/(D$4-$A6))/((1+D$4)^5)+Assumptions!$I$21-Assumptions!$I$22)/Assumptions!$I$23 | E6: =(SUM(DCF!B14:F14)+(DCF!F12*(1+$A6)/(E$4-$A6))/((1+E$4)^5)+Assumptions!$I$21-Assumptions!$I$22)/Assumptions!$I$23 | F6: =(SUM(DCF!B14:F14)+(DCF!F12*(1+$A6)/(F$4-$A6))/((1+F$4)^5)+Assumptions!$I$21-Assumptions!$I$22)/Assumptions!$I$23 | G6: =(SUM(DCF!B14:F14)+(DCF!F12*(1+$A6)/(G$4-$A6))/((1+G$4)^5)+Assumptions!$I$21-Assumptions!$I$22)/Assumptions!$I$23 | H6: =(SUM(DCF!B14:F14)+(DCF!F12*(1+$A6)/(H$4-$A6))/((1+H$4)^5)+Assumptions!$I$21-Assumptions!$I$22)/Assumptions!$I$23
A7: 0.03 | B7: =(SUM(DCF!B14:F14)+(DCF!F12*(1+$A7)/(B$4-$A7))/((1+B$4)^5)+Assumptions!$I$21-Assumptions!$I$22)/Assumptions!$I$23 | C7: =(SUM(DCF!B14:F14)+(DCF!F12*(1+$A7)/(C$4-$A7))/((1+C$4)^5)+Assumptions!$I$21-Assumptions!$I$22)/Assumptions!$I$23 | D7: =(SUM(DCF!B14:F14)+(DCF!F12*(1+$A7)/(D$4-$A7))/((1+D$4)^5)+Assumptions!$I$21-Assumptions!$I$22)/Assumptions!$I$23 | E7: =(SUM(DCF!B14:F14)+(DCF!F12*(1+$A7)/(E$4-$A7))/((1+E$4)^5)+Assumptions!$I$21-Assumptions!$I$22)/Assumptions!$I$23 | F7: =(SUM(DCF!B14:F14)+(DCF!F12*(1+$A7)/(F$4-$A7))/((1+F$4)^5)+Assumptions!$I$21-Assumptions!$I$22)/Assumptions!$I$23 | G7: =(SUM(DCF!B14:F14)+(DCF!F12*(1+$A7)/(G$4-$A7))/((1+G$4)^5)+Assumptions!$I$21-Assumptions!$I$22)/Assumptions!$I$23 | H7: =(SUM(DCF!B14:F14)+(DCF!F12*(1+$A7)/(H$4-$A7))/((1+H$4)^5)+Assumptions!$I$21-Assumptions!$I$22)/Assumptions!$I$23
A8: 0.035 | B8: =(SUM(DCF!B14:F14)+(DCF!F12*(1+$A8)/(B$4-$A8))/((1+B$4)^5)+Assumptions!$I$21-Assumptions!$I$22)/Assumptions!$I$23 | C8: =(SUM(DCF!B14:F14)+(DCF!F12*(1+$A8)/(C$4-$A8))/((1+C$4)^5)+Assumptions!$I$21-Assumptions!$I$22)/Assumptions!$I$23 | D8: =(SUM(DCF!B14:F14)+(DCF!F12*(1+$A8)/(D$4-$A8))/((1+D$4)^5)+Assumptions!$I$21-Assumptions!$I$22)/Assumptions!$I$23 | E8: =(SUM(DCF!B14:F14)+(DCF!F12*(1+$A8)/(E$4-$A8))/((1+E$4)^5)+Assumptions!$I$21-Assumptions!$I$22)/Assumptions!$I$23 | F8: =(SUM(DCF!B14:F14)+(DCF!F12*(1+$A8)/(F$4-$A8))/((1+F$4)^5)+Assumptions!$I$21-Assumptions!$I$22)/Assumptions!$I$23 | G8: =(SUM(DCF!B14:F14)+(DCF!F12*(1+$A8)/(G$4-$A8))/((1+G$4)^5)+Assumptions!$I$21-Assumptions!$I$22)/Assumptions!$I$23 | H8: =(SUM(DCF!B14:F14)+(DCF!F12*(1+$A8)/(H$4-$A8))/((1+H$4)^5)+Assumptions!$I$21-Assumptions!$I$22)/Assumptions!$I$23
A9: 0.04 | B9: =(SUM(DCF!B14:F14)+(DCF!F12*(1+$A9)/(B$4-$A9))/((1+B$4)^5)+Assumptions!$I$21-Assumptions!$I$22)/Assumptions!$I$23 | C9: =(SUM(DCF!B14:F14)+(DCF!F12*(1+$A9)/(C$4-$A9))/((1+C$4)^5)+Assumptions!$I$21-Assumptions!$I$22)/Assumptions!$I$23 | D9: =(SUM(DCF!B14:F14)+(DCF!F12*(1+$A9)/(D$4-$A9))/((1+D$4)^5)+Assumptions!$I$21-Assumptions!$I$22)/Assumptions!$I$23 | E9: =(SUM(DCF!B14:F14)+(DCF!F12*(1+$A9)/(E$4-$A9))/((1+E$4)^5)+Assumptions!$I$21-Assumptions!$I$22)/Assumptions!$I$23 | F9: =(SUM(DCF!B14:F14)+(DCF!F12*(1+$A9)/(F$4-$A9))/((1+F$4)^5)+Assumptions!$I$21-Assumptions!$I$22)/Assumptions!$I$23 | G9: =(SUM(DCF!B14:F14)+(DCF!F12*(1+$A9)/(G$4-$A9))/((1+G$4)^5)+Assumptions!$I$21-Assumptions!$I$22)/Assumptions!$I$23 | H9: =(SUM(DCF!B14:F14)+(DCF!F12*(1+$A9)/(H$4-$A9))/((1+H$4)^5)+Assumptions!$I$21-Assumptions!$I$22)/Assumptions!$I$23
A12: 数据图例 Data Legend:
A13: 蓝色字体 Blue Font = 财报原始数据 Hardcoded from financials
A14: 绿色字体 Green Font = 链接自其他工作表 Links from other sheets
A15: 蓝底深蓝字体 Blue Fill = 可编辑假设 Editable assumption inputs
A16: 黄底粗体 Yellow Fill = 关键输出 Key output rows
A17: 黑色字体 Black Font = 公式计算 Calculated from formulas
A19: 数据来源 Data Sources:
A20: • Alphabet 2025 10-K Annual Report (filed Feb 4, 2026) - Consolidated Financial Statements pp.48-52
A21: • Alphabet 2025 10-K Note 15: Segment Information (Google Services, Cloud, Other Bets)
A22: • Q4 2025 Earnings Call (Feb 4, 2026): CapEx 2026 guidance $75B (single quarter) → annualized ~$180B
A23: • 10Y UST yield ~4.2% (Feb 2026), Fed 2% long-term inflation target

Sheet Ratio_Analysis
A1: Financial Ratio Analysis 财务比率分析
A2: 单位：百分比或倍数 (% or Multiple)
B3: 2023 | C3: 2024 | D3: 2025 | E3: 2026E | F3: 2027E | G3: 2028E | H3: 2029E | I3: 2030E | K3: Notes / 预测逻辑
A5: Profitability 盈利能力
A6: Gross Margin 毛利率 | B6: =(Consolidated_PL!B5-Consolidated_PL!B14)/Consolidated_PL!B5 | C6: =(Consolidated_PL!C5-Consolidated_PL!C14)/Consolidated_PL!C5 | D6: =(Consolidated_PL!D5-Consolidated_PL!D14)/Consolidated_PL!D5 | E6: =(Consolidated_PL!E5-Consolidated_PL!E14)/Consolidated_PL!E5 | F6: =(Consolidated_PL!F5-Consolidated_PL!F14)/Consolidated_PL!F5 | G6: =(Consolidated_PL!G5-Consolidated_PL!G14)/Consolidated_PL!G5 | H6: =(Consolidated_PL!H5-Consolidated_PL!H14)/Consolidated_PL!H5 | I6: =(Consolidated_PL!I5-Consolidated_PL!I14)/Consolidated_PL!I5 | K6: 毛利/收入
A7: EBIT Margin 经营利润率 | B7: =Consolidated_PL!B26/Consolidated_PL!B5 | C7: =Consolidated_PL!C26/Consolidated_PL!C5 | D7: =Consolidated_PL!D26/Consolidated_PL!D5 | E7: =Consolidated_PL!E26/Consolidated_PL!E5 | F7: =Consolidated_PL!F26/Consolidated_PL!F5 | G7: =Consolidated_PL!G26/Consolidated_PL!G5 | H7: =Consolidated_PL!H26/Consolidated_PL!H5 | I7: =Consolidated_PL!I26/Consolidated_PL!I5 | K7: 经营利润/收入
A8: Net Margin 净利率 | B8: =Consolidated_PL!B33/Consolidated_PL!B5 | C8: =Consolidated_PL!C33/Consolidated_PL!C5 | D8: =Consolidated_PL!D33/Consolidated_PL!D5 | E8: =Consolidated_PL!E33/Consolidated_PL!E5 | F8: =Consolidated_PL!F33/Consolidated_PL!F5 | G8: =Consolidated_PL!G33/Consolidated_PL!G5 | H8: =Consolidated_PL!H33/Consolidated_PL!H5 | I8: =Consolidated_PL!I33/Consolidated_PL!I5 | K8: 净利润/收入
A9: ROE 净资产收益率 | B9: =Consolidated_PL!B33/BS!B40 | C9: =Consolidated_PL!C33/BS!C40 | D9: =Consolidated_PL!D33/BS!D40 | E9: =Consolidated_PL!E33/BS!E40 | F9: =Consolidated_PL!F33/BS!F40 | G9: =Consolidated_PL!G33/BS!G40 | H9: =Consolidated_PL!H33/BS!H40 | I9: =Consolidated_PL!I33/BS!I40 | K9: 净利润/股东权益
A10: ROA 总资产收益率 | B10: =Consolidated_PL!B33/BS!B21 | C10: =Consolidated_PL!C33/BS!C21 | D10: =Consolidated_PL!D33/BS!D21 | E10: =Consolidated_PL!E33/BS!E21 | F10: =Consolidated_PL!F33/BS!F21 | G10: =Consolidated_PL!G33/BS!G21 | H10: =Consolidated_PL!H33/BS!H21 | I10: =Consolidated_PL!I33/BS!I21 | K10: 净利润/总资产
A12: Operating Efficiency 营运效率
A13: AR Days 应收账款周转天数 | B13: =BS!B9/Consolidated_PL!B5*365 | C13: =BS!C9/Consolidated_PL!C5*365 | D13: =BS!D9/Consolidated_PL!D5*365 | E13: =BS!E9/Consolidated_PL!E5*365 | F13: =BS!F9/Consolidated_PL!F5*365 | G13: =BS!G9/Consolidated_PL!G5*365 | H13: =BS!H9/Consolidated_PL!H5*365 | I13: =BS!I9/Consolidated_PL!I5*365 | K13: 应收/收入×365
A14: AP Days 应付账款周转天数 | B14: =BS!B24/Consolidated_PL!B14*365 | C14: =BS!C24/Consolidated_PL!C14*365 | D14: =BS!D24/Consolidated_PL!D14*365 | E14: =BS!E24/Consolidated_PL!E14*365 | F14: =BS!F24/Consolidated_PL!F14*365 | G14: =BS!G24/Consolidated_PL!G14*365 | H14: =BS!H24/Consolidated_PL!H14*365 | I14: =BS!I24/Consolidated_PL!I14*365 | K14: 应付/COGS×365
A15: CapEx Intensity 资本支出强度 | B15: =-Cash_Flow!B26/Consolidated_PL!B5 | C15: =-Cash_Flow!C26/Consolidated_PL!C5 | D15: =-Cash_Flow!D26/Consolidated_PL!D5 | E15: =-Cash_Flow!E26/Consolidated_PL!E5 | F15: =-Cash_Flow!F26/Consolidated_PL!F5 | G15: =-Cash_Flow!G26/Consolidated_PL!G5 | H15: =-Cash_Flow!H26/Consolidated_PL!H5 | I15: =-Cash_Flow!I26/Consolidated_PL!I5 | K15: |CapEx|/Revenue
A16: CapEx / D&A 资本支出/折旧 | B16: =-Cash_Flow!B26/Consolidated_PL!B37 | C16: =-Cash_Flow!C26/Consolidated_PL!C37 | D16: =-Cash_Flow!D26/Consolidated_PL!D37 | E16: =-Cash_Flow!E26/Consolidated_PL!E37 | F16: =-Cash_Flow!F26/Consolidated_PL!F37 | G16: =-Cash_Flow!G26/Consolidated_PL!G37 | H16: =-Cash_Flow!H26/Consolidated_PL!H37 | I16: =-Cash_Flow!I26/Consolidated_PL!I37 | K16: >1x表示净投资增长
A18: Leverage 杠杆与偿债能力
A19: Debt / Assets 资产负债率 | B19: =(BS!B21-BS!B40)/BS!B21 | C19: =(BS!C21-BS!C40)/BS!C21 | D19: =(BS!D21-BS!D40)/BS!D21 | E19: =(BS!E21-BS!E40)/BS!E21 | F19: =(BS!F21-BS!F40)/BS!F21 | G19: =(BS!G21-BS!G40)/BS!G21 | H19: =(BS!H21-BS!H40)/BS!H21 | I19: =(BS!I21-BS!I40)/BS!I21 | K19: 总负债/总资产
A20: Current Ratio 流动比率 | B20: =BS!B11/BS!B29 | C20: =BS!C11/BS!C29 | D20: =BS!D11/BS!D29 | E20: =BS!E11/BS!E29 | F20: =BS!F11/BS!F29 | G20: =BS!G11/BS!G29 | H20: =BS!H11/BS!H29 | I20: =BS!I11/BS!I29 | K20: 流动资产/流动负债
A21: Net Cash 净现金 (mm) | B21: =BS!B8-BS!B32 | C21: =BS!C8-BS!C32 | D21: =BS!D8-BS!D32 | E21: =BS!E8-BS!E32 | F21: =BS!F8-BS!F32 | G21: =BS!G8-BS!G32 | H21: =BS!H8-BS!H32 | I21: =BS!I8-BS!I32 | K21: 现金+证券-长期债务
A23: Cash Flow Quality 现金流质量
A24: OCF / Net Income 经营现金流/净利润 | B24: =Cash_Flow!B23/Consolidated_PL!B33 | C24: =Cash_Flow!C23/Consolidated_PL!C33 | D24: =Cash_Flow!D23/Consolidated_PL!D33 | E24: =Cash_Flow!E23/Consolidated_PL!E33 | F24: =Cash_Flow!F23/Consolidated_PL!F33 | G24: =Cash_Flow!G23/Consolidated_PL!G33 | H24: =Cash_Flow!H23/Consolidated_PL!H33 | I24: =Cash_Flow!I23/Consolidated_PL!I33 | K24: 现金流质量，>1为佳
A25: FCF / Revenue 自由现金流率 | B25: =Cash_Flow!B34/Consolidated_PL!B5 | C25: =Cash_Flow!C34/Consolidated_PL!C5 | D25: =Cash_Flow!D34/Consolidated_PL!D5 | E25: =Cash_Flow!E34/Consolidated_PL!E5 | F25: =Cash_Flow!F34/Consolidated_PL!F5 | G25: =Cash_Flow!G34/Consolidated_PL!G5 | H25: =Cash_Flow!H34/Consolidated_PL!H5 | I25: =Cash_Flow!I34/Consolidated_PL!I5 | K25: FCF/Revenue
A27: Growth 增长指标
A28: Revenue Growth 收入增速 | C28: =Consolidated_PL!C5/Consolidated_PL!B5-1 | D28: =Consolidated_PL!D5/Consolidated_PL!C5-1 | E28: =Consolidated_PL!E5/Consolidated_PL!D5-1 | F28: =Consolidated_PL!F5/Consolidated_PL!E5-1 | G28: =Consolidated_PL!G5/Consolidated_PL!F5-1 | H28: =Consolidated_PL!H5/Consolidated_PL!G5-1 | I28: =Consolidated_PL!I5/Consolidated_PL!H5-1 | K28: YoY
A29: Net Income Growth 净利润增速 | C29: =Consolidated_PL!C33/Consolidated_PL!B33-1 | D29: =Consolidated_PL!D33/Consolidated_PL!C33-1 | E29: =Consolidated_PL!E33/Consolidated_PL!D33-1 | F29: =Consolidated_PL!F33/Consolidated_PL!E33-1 | G29: =Consolidated_PL!G33/Consolidated_PL!F33-1 | H29: =Consolidated_PL!H33/Consolidated_PL!G33-1 | I29: =Consolidated_PL!I33/Consolidated_PL!H33-1 | K29: YoY
A30: EPS Growth 每股收益增速 | C30: =Consolidated_PL!C41/Consolidated_PL!B41-1 | D30: =Consolidated_PL!D41/Consolidated_PL!C41-1 | E30: =Consolidated_PL!E41/Consolidated_PL!D41-1 | F30: =Consolidated_PL!F41/Consolidated_PL!E41-1 | G30: =Consolidated_PL!G41/Consolidated_PL!F41-1 | H30: =Consolidated_PL!H41/Consolidated_PL!G41-1 | I30: =Consolidated_PL!I41/Consolidated_PL!H41-1 | K30: YoY
A32: Key Investment Highlights 关键投资亮点
A33: ✓ AI驱动搜索广告持续增长，Search revenue占比>55%，核心现金牛
A34: ✓ Google Cloud 48% YoY增长(Q4'25)，利润率从5%→24%快速改善
A35: ✓ CapEx高峰期(2026 ~$180B)，AI基础设施投资确立长期竞争优势
A36: ✓ 大规模回购+首次派息($0.83/share)，股东回报显著增强
A37: ✓ Net cash position >$80B，资产负债表极其稳健
A38: ⚠ 风险: AI CapEx回报期不确定、DOJ反垄断诉讼、Cloud竞争加剧
A39: ⚠ 风险: 2025 OI&E含$24B非上市证券估值收益(不可持续)
A42: 数据图例 Data Legend:
A43: 蓝色字体 Blue Font = 财报原始数据 Hardcoded from financials
A44: 绿色字体 Green Font = 链接自其他工作表 Links from other sheets
A45: 蓝底深蓝字体 Blue Fill = 可编辑假设 Editable assumption inputs
... A53: • 10Y UST yield ~4.2% (Feb 2026), Fed 2% long-term inflation target
